



<HTML><HEAD>

<TITLE>December 1997/Error Handling with C++ Exceptions, Part 2/Listing 2</TITLE></HEAD>
<BODY BACKGROUND="" BGCOLOR="#FFFFFF" TEXT="#000000">
<h4>Listing 2:	Deallocates a resource in the midst of handling an exception</h4>

<pre>
// destroy4.cpp
#include &lt;stdio.h&gt;

main()
{
    void f(const char*);
    try
    {
        f("file1.dat");
    }
    catch(int)
    {
        puts("Caught exception");
    }
}

void f(const char* fname)
{
    FILE* fp = fopen(fname,"r");
    if (fp)
    {
        try
        {
            throw 1;
        }
        catch(int)
        {
            fclose(fp);
            puts("File closed");
            throw;  // Re-throw
        }

        fclose(fp); // The normal close
    }
}

// Output:
File closed
Caught exception
//End of File
</pre>
</body></html>
